---
title: Try... Catch... Instrucción finally - Visual Basic
description: Aprenda a usar con Visual Basic Try/Catch/Finally, instrucciones de control de excepciones.
ms.date: 12/07/2018
f1_keywords:
- vb.Try...Catch...Finally
- vb.when
- vb.Finally
- vb.Catch
- vb.Try
helpviewer_keywords:
- Try...Catch...Finally statements
- Try statement [Visual Basic]
- try-catch exception handling, Try...Catch...Finally statements
- error handling, while running code
- Try statement [Visual Basic], Try...Catch...Finally
- Finally keyword [Visual Basic], Try...Catch...Finally
- Catch statement [Visual Basic]
- When keyword [Visual Basic]
- Visual Basic code, handling errors while running
- structured exception handling, Try...Catch...Finally statements
ms.assetid: d6488026-ccb3-42b8-a810-0d97b9d6472b
ms.custom: seodec18
ms.openlocfilehash: 2e4fef836b08f536565105dbab76292b2fc4388e
ms.sourcegitcommit: 9b552addadfb57fab0b9e7852ed4f1f1b8a42f8e
ms.translationtype: MT
ms.contentlocale: es-ES
ms.lasthandoff: 04/23/2019
ms.locfileid: "61934269"
---
# <a name="trycatchfinally-statement-visual-basic"></a><span data-ttu-id="b6d2a-103">Instrucción Try...Catch...Finally (Visual Basic)</span><span class="sxs-lookup"><span data-stu-id="b6d2a-103">Try...Catch...Finally Statement (Visual Basic)</span></span>

<span data-ttu-id="b6d2a-104">Proporciona un medio para controlar algunos o todos los errores posibles que pueden producirse en un determinado bloque de código, mientras sigue ejecutando el código.</span><span class="sxs-lookup"><span data-stu-id="b6d2a-104">Provides a way to handle some or all possible errors that may occur in a given block of code, while still running code.</span></span>

## <a name="syntax"></a><span data-ttu-id="b6d2a-105">Sintaxis</span><span class="sxs-lookup"><span data-stu-id="b6d2a-105">Syntax</span></span>

```vb
Try
    [ tryStatements ]
    [ Exit Try ]
[ Catch [ exception [ As type ] ] [ When expression ]
    [ catchStatements ]
    [ Exit Try ] ]
[ Catch ... ]
[ Finally
    [ finallyStatements ] ]
End Try
```

## <a name="parts"></a><span data-ttu-id="b6d2a-106">Elementos</span><span class="sxs-lookup"><span data-stu-id="b6d2a-106">Parts</span></span>

|<span data-ttu-id="b6d2a-107">Término</span><span class="sxs-lookup"><span data-stu-id="b6d2a-107">Term</span></span>|<span data-ttu-id="b6d2a-108">Definición</span><span class="sxs-lookup"><span data-stu-id="b6d2a-108">Definition</span></span>|
|---|---|
|`tryStatements`|<span data-ttu-id="b6d2a-109">Opcional.</span><span class="sxs-lookup"><span data-stu-id="b6d2a-109">Optional.</span></span> <span data-ttu-id="b6d2a-110">Instrucciones donde puede producirse un error.</span><span class="sxs-lookup"><span data-stu-id="b6d2a-110">Statement(s) where an error can occur.</span></span> <span data-ttu-id="b6d2a-111">Puede ser una instrucción compuesta.</span><span class="sxs-lookup"><span data-stu-id="b6d2a-111">Can be a compound statement.</span></span>|
|`Catch`|<span data-ttu-id="b6d2a-112">Opcional.</span><span class="sxs-lookup"><span data-stu-id="b6d2a-112">Optional.</span></span> <span data-ttu-id="b6d2a-113">Varios `Catch` bloques permitido.</span><span class="sxs-lookup"><span data-stu-id="b6d2a-113">Multiple `Catch` blocks permitted.</span></span> <span data-ttu-id="b6d2a-114">Si se produce una excepción al procesar el `Try` bloquear cada `Catch` instrucción se examina en orden textual para determinar si controla la excepción, con `exception` que representa la excepción que se ha producido.</span><span class="sxs-lookup"><span data-stu-id="b6d2a-114">If an exception occurs when processing the `Try` block, each `Catch` statement is examined in textual order to determine whether it handles the exception, with `exception` representing the exception that has been thrown.</span></span>|
|`exception`|<span data-ttu-id="b6d2a-115">Opcional.</span><span class="sxs-lookup"><span data-stu-id="b6d2a-115">Optional.</span></span> <span data-ttu-id="b6d2a-116">Cualquier nombre de variable.</span><span class="sxs-lookup"><span data-stu-id="b6d2a-116">Any variable name.</span></span> <span data-ttu-id="b6d2a-117">El valor inicial de `exception` es el valor del error producido.</span><span class="sxs-lookup"><span data-stu-id="b6d2a-117">The initial value of `exception` is the value of the thrown error.</span></span> <span data-ttu-id="b6d2a-118">Puede usar con `Catch` especificar el error detectada.</span><span class="sxs-lookup"><span data-stu-id="b6d2a-118">Used with `Catch` to specify the error caught.</span></span> <span data-ttu-id="b6d2a-119">Si se omite, el `Catch` instrucción detecta cualquier excepción.</span><span class="sxs-lookup"><span data-stu-id="b6d2a-119">If omitted, the `Catch` statement catches any exception.</span></span>|
|`type`|<span data-ttu-id="b6d2a-120">Opcional.</span><span class="sxs-lookup"><span data-stu-id="b6d2a-120">Optional.</span></span> <span data-ttu-id="b6d2a-121">Especifica el tipo de filtro de la clase.</span><span class="sxs-lookup"><span data-stu-id="b6d2a-121">Specifies the type of class filter.</span></span> <span data-ttu-id="b6d2a-122">Si el valor de `exception` es del tipo especificado por `type` o de un tipo derivado, el identificador se enlaza al objeto de excepción.</span><span class="sxs-lookup"><span data-stu-id="b6d2a-122">If the value of `exception` is of the type specified by `type` or of a derived type, the identifier becomes bound to the exception object.</span></span>|
|`When`|<span data-ttu-id="b6d2a-123">Opcional.</span><span class="sxs-lookup"><span data-stu-id="b6d2a-123">Optional.</span></span> <span data-ttu-id="b6d2a-124">Un `Catch` instrucción con un `When` cláusula detecta las excepciones solo cuando `expression` se evalúa como `True`.</span><span class="sxs-lookup"><span data-stu-id="b6d2a-124">A `Catch` statement with a `When` clause catches exceptions only when `expression` evaluates to `True`.</span></span> <span data-ttu-id="b6d2a-125">Un `When` cláusula se aplica solo después de comprobar el tipo de la excepción, y `expression` pueden hacer referencia al identificador que representa la excepción.</span><span class="sxs-lookup"><span data-stu-id="b6d2a-125">A `When` clause is applied only after checking the type of the exception, and `expression` may refer to the identifier representing the exception.</span></span>|
|`expression`|<span data-ttu-id="b6d2a-126">Opcional.</span><span class="sxs-lookup"><span data-stu-id="b6d2a-126">Optional.</span></span> <span data-ttu-id="b6d2a-127">Debe poder convertirse implícitamente a `Boolean`.</span><span class="sxs-lookup"><span data-stu-id="b6d2a-127">Must be implicitly convertible to `Boolean`.</span></span> <span data-ttu-id="b6d2a-128">Cualquier expresión que describe un filtro genérico.</span><span class="sxs-lookup"><span data-stu-id="b6d2a-128">Any expression that describes a generic filter.</span></span> <span data-ttu-id="b6d2a-129">Se utiliza normalmente para filtrar por número de error.</span><span class="sxs-lookup"><span data-stu-id="b6d2a-129">Typically used to filter by error number.</span></span> <span data-ttu-id="b6d2a-130">Puede usar con `When` palabra clave para especificar las circunstancias bajo las que se captura el error.</span><span class="sxs-lookup"><span data-stu-id="b6d2a-130">Used with `When` keyword to specify circumstances under which the error is caught.</span></span>|
|`catchStatements`|<span data-ttu-id="b6d2a-131">Opcional.</span><span class="sxs-lookup"><span data-stu-id="b6d2a-131">Optional.</span></span> <span data-ttu-id="b6d2a-132">Instrucciones para controlar los errores que ocurren en el asociado `Try` bloque.</span><span class="sxs-lookup"><span data-stu-id="b6d2a-132">Statement(s) to handle errors that occur in the associated `Try` block.</span></span> <span data-ttu-id="b6d2a-133">Puede ser una instrucción compuesta.</span><span class="sxs-lookup"><span data-stu-id="b6d2a-133">Can be a compound statement.</span></span>|
|`Exit Try`|<span data-ttu-id="b6d2a-134">Opcional.</span><span class="sxs-lookup"><span data-stu-id="b6d2a-134">Optional.</span></span> <span data-ttu-id="b6d2a-135">Palabra clave que interrumpe fuera de la `Try...Catch...Finally` estructura.</span><span class="sxs-lookup"><span data-stu-id="b6d2a-135">Keyword that breaks out of the `Try...Catch...Finally` structure.</span></span> <span data-ttu-id="b6d2a-136">Reanuda la ejecución con el código que sigue inmediatamente el `End Try` instrucción.</span><span class="sxs-lookup"><span data-stu-id="b6d2a-136">Execution resumes with the code immediately following the `End Try` statement.</span></span> <span data-ttu-id="b6d2a-137">El `Finally` todavía se ejecutará la instrucción.</span><span class="sxs-lookup"><span data-stu-id="b6d2a-137">The `Finally` statement will still be executed.</span></span> <span data-ttu-id="b6d2a-138">No se permite en `Finally` bloques.</span><span class="sxs-lookup"><span data-stu-id="b6d2a-138">Not allowed in `Finally` blocks.</span></span>|
|`Finally`|<span data-ttu-id="b6d2a-139">Opcional.</span><span class="sxs-lookup"><span data-stu-id="b6d2a-139">Optional.</span></span> <span data-ttu-id="b6d2a-140">Un `Finally` bloque siempre se ejecuta cuando la ejecución sale de cualquier parte de la `Try...Catch` instrucción.</span><span class="sxs-lookup"><span data-stu-id="b6d2a-140">A `Finally` block is always executed when execution leaves any part of the `Try...Catch` statement.</span></span>|
|`finallyStatements`|<span data-ttu-id="b6d2a-141">Opcional.</span><span class="sxs-lookup"><span data-stu-id="b6d2a-141">Optional.</span></span> <span data-ttu-id="b6d2a-142">Instrucciones que se ejecutan una vez realizado el resto del procesamiento de error.</span><span class="sxs-lookup"><span data-stu-id="b6d2a-142">Statement(s) that are executed after all other error processing has occurred.</span></span>|
|`End Try`|<span data-ttu-id="b6d2a-143">Finaliza el `Try...Catch...Finally` estructura.</span><span class="sxs-lookup"><span data-stu-id="b6d2a-143">Terminates the `Try...Catch...Finally` structure.</span></span>|

## <a name="remarks"></a><span data-ttu-id="b6d2a-144">Comentarios</span><span class="sxs-lookup"><span data-stu-id="b6d2a-144">Remarks</span></span>

<span data-ttu-id="b6d2a-145">Si espera que podría producirse una excepción determinada en una sección concreta del código, coloque el código en un `Try` bloquear y usar un `Catch` bloque para conservar el control y controlar la excepción si se produce.</span><span class="sxs-lookup"><span data-stu-id="b6d2a-145">If you expect that a particular exception might occur during a particular section of code, put the code in a `Try` block and use a `Catch` block to retain control and handle the exception if it occurs.</span></span>

<span data-ttu-id="b6d2a-146">Un `Try…Catch` instrucción consta de un `Try` bloque seguido de uno o varios `Catch` cláusulas, que especifican controladores para diferentes excepciones.</span><span class="sxs-lookup"><span data-stu-id="b6d2a-146">A `Try…Catch` statement consists of a `Try` block followed by one or more `Catch` clauses, which specify handlers for various exceptions.</span></span> <span data-ttu-id="b6d2a-147">Cuando se produce una excepción un `Try` bloquear, Visual Basic busca el `Catch` instrucción que controla la excepción.</span><span class="sxs-lookup"><span data-stu-id="b6d2a-147">When an exception is thrown in a `Try` block, Visual Basic looks for the `Catch` statement that handles the exception.</span></span> <span data-ttu-id="b6d2a-148">Si una coincidencia `Catch` no se encontró la instrucción, Visual Basic examina el método que llamó al método actual, y así sucesivamente hasta la pila de llamadas.</span><span class="sxs-lookup"><span data-stu-id="b6d2a-148">If a matching `Catch` statement is not found, Visual Basic examines the method that called the current method, and so on up the call stack.</span></span> <span data-ttu-id="b6d2a-149">Si no hay ningún `Catch` bloque se encuentra, Visual Basic muestra un mensaje de excepción no controlada al usuario y se detiene la ejecución del programa.</span><span class="sxs-lookup"><span data-stu-id="b6d2a-149">If no `Catch` block is found, Visual Basic displays an unhandled exception message to the user and stops execution of the program.</span></span>

<span data-ttu-id="b6d2a-150">Puede utilizar más de uno `Catch` instrucción en un `Try…Catch` instrucción.</span><span class="sxs-lookup"><span data-stu-id="b6d2a-150">You can use more than one `Catch` statement in a `Try…Catch` statement.</span></span> <span data-ttu-id="b6d2a-151">Si lo hace, el orden de los `Catch` cláusulas es importante, ya que se examinan en orden.</span><span class="sxs-lookup"><span data-stu-id="b6d2a-151">If you do this, the order of the `Catch` clauses is significant because they are examined in order.</span></span> <span data-ttu-id="b6d2a-152">Detectar las excepciones más específicas antes que las menos específicas.</span><span class="sxs-lookup"><span data-stu-id="b6d2a-152">Catch the more specific exceptions before the less specific ones.</span></span>

<span data-ttu-id="b6d2a-153">La siguiente `Catch` condiciones de instrucción son las menos específicas e interceptará todas las excepciones que derivan de la <xref:System.Exception> clase.</span><span class="sxs-lookup"><span data-stu-id="b6d2a-153">The following `Catch` statement conditions are the least specific, and will catch all exceptions that derive from the <xref:System.Exception> class.</span></span> <span data-ttu-id="b6d2a-154">Normalmente debe usar una de estas variaciones como el último `Catch` bloque en el `Try...Catch...Finally` estructura después de detectar todas las excepciones específicas que espera.</span><span class="sxs-lookup"><span data-stu-id="b6d2a-154">You should ordinarily use one of these variations as the last `Catch` block in the `Try...Catch...Finally` structure, after catching all the specific exceptions you expect.</span></span> <span data-ttu-id="b6d2a-155">Flujo de control nunca puede alcanzar un `Catch` bloque que sigue a cualquiera de estas variaciones.</span><span class="sxs-lookup"><span data-stu-id="b6d2a-155">Control flow can never reach a `Catch` block that follows either of these variations.</span></span>

- <span data-ttu-id="b6d2a-156">El `type` es `Exception`, por ejemplo: `Catch ex As Exception`</span><span class="sxs-lookup"><span data-stu-id="b6d2a-156">The `type` is `Exception`, for example: `Catch ex As Exception`</span></span>

- <span data-ttu-id="b6d2a-157">La instrucción no tiene ningún `exception` variable, por ejemplo: `Catch`</span><span class="sxs-lookup"><span data-stu-id="b6d2a-157">The statement has no `exception` variable, for example: `Catch`</span></span>

<span data-ttu-id="b6d2a-158">Cuando un `Try…Catch…Finally` instrucción está anidada en otro `Try` bloque, Visual Basic, en primer lugar examina cada `Catch` instrucción interior `Try` bloque.</span><span class="sxs-lookup"><span data-stu-id="b6d2a-158">When a `Try…Catch…Finally` statement is nested in another `Try` block, Visual Basic first examines each `Catch` statement in the innermost `Try` block.</span></span> <span data-ttu-id="b6d2a-159">Si no hay coincidencia `Catch` se encuentra una instrucción, la búsqueda continúa en el `Catch` las instrucciones de la exterior `Try…Catch…Finally` bloque.</span><span class="sxs-lookup"><span data-stu-id="b6d2a-159">If no matching `Catch` statement is found, the search proceeds to the `Catch` statements of the outer `Try…Catch…Finally` block.</span></span>

<span data-ttu-id="b6d2a-160">Las variables locales de un `Try` bloque no están disponibles en un `Catch` bloquear porque son bloques independientes.</span><span class="sxs-lookup"><span data-stu-id="b6d2a-160">Local variables from a `Try` block are not available in a `Catch` block because they are separate blocks.</span></span> <span data-ttu-id="b6d2a-161">Si desea utilizar una variable en más de un bloque, declare la variable fuera del `Try...Catch...Finally` estructura.</span><span class="sxs-lookup"><span data-stu-id="b6d2a-161">If you want to use a variable in more than one block, declare the variable outside the `Try...Catch...Finally` structure.</span></span>

> [!TIP]
> <span data-ttu-id="b6d2a-162">El `Try…Catch…Finally` instrucción está disponible como un fragmento de código de IntelliSense.</span><span class="sxs-lookup"><span data-stu-id="b6d2a-162">The `Try…Catch…Finally` statement is available as an IntelliSense code snippet.</span></span> <span data-ttu-id="b6d2a-163">En el Administrador de fragmentos de código, expanda **patrones de código: si, For Each, Try Catch, propiedad, etcetera**y, a continuación, **control de errores (excepciones)**.</span><span class="sxs-lookup"><span data-stu-id="b6d2a-163">In the Code Snippets Manager, expand **Code Patterns - If, For Each, Try Catch, Property, etc**, and then **Error Handling (Exceptions)**.</span></span> <span data-ttu-id="b6d2a-164">Para obtener más información, vea [Fragmentos de código](/visualstudio/ide/code-snippets).</span><span class="sxs-lookup"><span data-stu-id="b6d2a-164">For more information, see [Code Snippets](/visualstudio/ide/code-snippets).</span></span>

## <a name="finally-block"></a><span data-ttu-id="b6d2a-165">Bloque finally</span><span class="sxs-lookup"><span data-stu-id="b6d2a-165">Finally block</span></span>

<span data-ttu-id="b6d2a-166">Si tiene una o varias instrucciones que se deben ejecutar antes de salir el `Try` estructura, utilice un `Finally` bloque.</span><span class="sxs-lookup"><span data-stu-id="b6d2a-166">If you have one or more statements that must run before you exit the `Try` structure, use a `Finally` block.</span></span> <span data-ttu-id="b6d2a-167">El control pasa a la `Finally` bloquear justo antes de pasar fuera de la `Try…Catch` estructura.</span><span class="sxs-lookup"><span data-stu-id="b6d2a-167">Control passes to the `Finally` block just before it passes out of the `Try…Catch` structure.</span></span> <span data-ttu-id="b6d2a-168">Esto es cierto incluso si se produce una excepción en cualquier lugar dentro de la `Try` estructura.</span><span class="sxs-lookup"><span data-stu-id="b6d2a-168">This is true even if an exception occurs anywhere inside the `Try` structure.</span></span>

<span data-ttu-id="b6d2a-169">Un `Finally` bloque es útil para ejecutar cualquier código que deba ejecutarse incluso si hay una excepción.</span><span class="sxs-lookup"><span data-stu-id="b6d2a-169">A `Finally` block is useful for running any code that must execute even if there is an exception.</span></span> <span data-ttu-id="b6d2a-170">El control pasa a la `Finally` bloque independientemente de cómo el `Try...Catch` bloquear se cierra.</span><span class="sxs-lookup"><span data-stu-id="b6d2a-170">Control is passed to the `Finally` block regardless of how the `Try...Catch` block exits.</span></span>

<span data-ttu-id="b6d2a-171">El código en un `Finally` bloque se ejecuta incluso si el código encuentra una `Return` instrucción en un `Try` o `Catch` bloque.</span><span class="sxs-lookup"><span data-stu-id="b6d2a-171">The code in a `Finally` block runs even if your code encounters a `Return` statement in a `Try` or `Catch` block.</span></span> <span data-ttu-id="b6d2a-172">El control no pasar de un `Try` o `Catch` bloquear correspondiente `Finally` bloquear en los casos siguientes:</span><span class="sxs-lookup"><span data-stu-id="b6d2a-172">Control does not pass from a `Try` or `Catch` block to the corresponding `Finally` block in the following cases:</span></span>

- <span data-ttu-id="b6d2a-173">Un [instrucción End](end-statement.md) se encuentra en la `Try` o `Catch` bloque.</span><span class="sxs-lookup"><span data-stu-id="b6d2a-173">An [End Statement](end-statement.md) is encountered in the `Try` or `Catch` block.</span></span>

- <span data-ttu-id="b6d2a-174">Un <xref:System.StackOverflowException> se produce en el `Try` o `Catch` bloque.</span><span class="sxs-lookup"><span data-stu-id="b6d2a-174">A <xref:System.StackOverflowException> is thrown in the `Try` or `Catch` block.</span></span>

<span data-ttu-id="b6d2a-175">No es válido para transferir explícitamente la ejecución en un `Finally` bloque.</span><span class="sxs-lookup"><span data-stu-id="b6d2a-175">It is not valid to explicitly transfer execution into a `Finally` block.</span></span> <span data-ttu-id="b6d2a-176">Transferir la ejecución de un `Finally` bloque no es válido, excepto a través de una excepción.</span><span class="sxs-lookup"><span data-stu-id="b6d2a-176">Transferring execution out of a `Finally` block is not valid, except through an exception.</span></span>

<span data-ttu-id="b6d2a-177">Si un `Try` instrucción no contenga al menos una `Catch` bloque, que debe contener un `Finally` bloque.</span><span class="sxs-lookup"><span data-stu-id="b6d2a-177">If a `Try` statement does not contain at least one `Catch` block, it must contain a `Finally` block.</span></span>

> [!TIP]
> <span data-ttu-id="b6d2a-178">Si no tiene que detectar excepciones específicas, la `Using` instrucción se comporta como un `Try…Finally` bloque y garantiza la disposición de los recursos, independientemente de cómo salga el bloque.</span><span class="sxs-lookup"><span data-stu-id="b6d2a-178">If you do not have to catch specific exceptions, the `Using` statement behaves like a `Try…Finally` block, and guarantees disposal of the resources, regardless of how you exit the block.</span></span> <span data-ttu-id="b6d2a-179">Esto es cierto incluso con una excepción no controlada.</span><span class="sxs-lookup"><span data-stu-id="b6d2a-179">This is true even with an unhandled exception.</span></span> <span data-ttu-id="b6d2a-180">Para obtener más información, vea [Using (Instrucción)](using-statement.md).</span><span class="sxs-lookup"><span data-stu-id="b6d2a-180">For more information, see [Using Statement](using-statement.md).</span></span>

## <a name="exception-argument"></a><span data-ttu-id="b6d2a-181">Argumento de excepción</span><span class="sxs-lookup"><span data-stu-id="b6d2a-181">Exception argument</span></span>

<span data-ttu-id="b6d2a-182">El `Catch` bloque `exception` argumento es una instancia de la <xref:System.Exception> clase o una clase que deriva la `Exception` clase.</span><span class="sxs-lookup"><span data-stu-id="b6d2a-182">The `Catch` block `exception` argument is an instance of the <xref:System.Exception> class or a class that derives from the `Exception` class.</span></span> <span data-ttu-id="b6d2a-183">El `Exception` instancia de la clase que corresponde al error que se produjeron en el `Try` bloque.</span><span class="sxs-lookup"><span data-stu-id="b6d2a-183">The `Exception` class instance corresponds to the error that occurred in the `Try` block.</span></span>

<span data-ttu-id="b6d2a-184">Las propiedades de la `Exception` objeto ayuda a identificar la causa y la ubicación de una excepción.</span><span class="sxs-lookup"><span data-stu-id="b6d2a-184">The properties of the `Exception` object help to identify the cause and location of an exception.</span></span> <span data-ttu-id="b6d2a-185">Por ejemplo, el <xref:System.Exception.StackTrace%2A> listas de propiedades de los métodos llamados que produjeron la excepción, lo que le ayuda a encontrar dónde se produjo el error en el código.</span><span class="sxs-lookup"><span data-stu-id="b6d2a-185">For example, the <xref:System.Exception.StackTrace%2A> property lists the called methods that led to the exception, helping you find where the error occurred in the code.</span></span> <span data-ttu-id="b6d2a-186"><xref:System.Exception.Message%2A> Devuelve un mensaje que describe la excepción.</span><span class="sxs-lookup"><span data-stu-id="b6d2a-186"><xref:System.Exception.Message%2A> returns a message that describes the exception.</span></span> <span data-ttu-id="b6d2a-187"><xref:System.Exception.HelpLink%2A> Devuelve un vínculo a un archivo de ayuda asociado.</span><span class="sxs-lookup"><span data-stu-id="b6d2a-187"><xref:System.Exception.HelpLink%2A> returns a link to an associated Help file.</span></span> <span data-ttu-id="b6d2a-188"><xref:System.Exception.InnerException%2A> Devuelve el `Exception` devuelve el objeto que produjo la excepción actual, o bien `Nothing` si no hay ningún original `Exception`.</span><span class="sxs-lookup"><span data-stu-id="b6d2a-188"><xref:System.Exception.InnerException%2A> returns the `Exception` object that caused the current exception, or it returns `Nothing` if there is no original `Exception`.</span></span>

## <a name="considerations-when-using-a-trycatch-statement"></a><span data-ttu-id="b6d2a-189">Consideraciones al usar un bloque Try... Catch (instrucción)</span><span class="sxs-lookup"><span data-stu-id="b6d2a-189">Considerations when using a Try…Catch statement</span></span>

<span data-ttu-id="b6d2a-190">Use un `Try…Catch` instrucción sólo para señalar la aparición de eventos del programa inusual o inesperados.</span><span class="sxs-lookup"><span data-stu-id="b6d2a-190">Use a `Try…Catch` statement only to signal the occurrence of unusual or unanticipated program events.</span></span> <span data-ttu-id="b6d2a-191">Razones para esto incluyen lo siguiente:</span><span class="sxs-lookup"><span data-stu-id="b6d2a-191">Reasons for this include the following:</span></span>

- <span data-ttu-id="b6d2a-192">Detectar excepciones en tiempo de ejecución crea una sobrecarga adicional y es probable que sea más lenta que la comprobación previa para evitar las excepciones.</span><span class="sxs-lookup"><span data-stu-id="b6d2a-192">Catching exceptions at runtime creates additional overhead, and is likely to be slower than pre-checking to avoid exceptions.</span></span>

- <span data-ttu-id="b6d2a-193">Si un `Catch` bloque no se administra correctamente, la excepción podría no mostrarse correctamente a los usuarios.</span><span class="sxs-lookup"><span data-stu-id="b6d2a-193">If a `Catch` block is not handled correctly, the exception might not be reported correctly to users.</span></span>

- <span data-ttu-id="b6d2a-194">Control de excepciones hace que sea un programa más complejo.</span><span class="sxs-lookup"><span data-stu-id="b6d2a-194">Exception handling makes a program more complex.</span></span>

<span data-ttu-id="b6d2a-195">No necesita siempre un `Try…Catch` instrucción para comprobar una condición que es probable que ocurra.</span><span class="sxs-lookup"><span data-stu-id="b6d2a-195">You do not always need a `Try…Catch` statement to check for a condition that is likely to occur.</span></span> <span data-ttu-id="b6d2a-196">El ejemplo siguiente comprueba si existe un archivo antes de intentar abrirlo.</span><span class="sxs-lookup"><span data-stu-id="b6d2a-196">The following example checks whether a file exists before trying to open it.</span></span> <span data-ttu-id="b6d2a-197">Esto reduce la necesidad de detectar una excepción producida por el <xref:System.IO.File.OpenText%2A> método.</span><span class="sxs-lookup"><span data-stu-id="b6d2a-197">This reduces the need for catching an exception thrown by the <xref:System.IO.File.OpenText%2A> method.</span></span>

[!code-vb[VbVbalrStatements#94](~/samples/snippets/visualbasic/VS_Snippets_VBCSharp/VbVbalrStatements/VB/Class1.vb#94)]

<span data-ttu-id="b6d2a-198">Asegúrese de que el código en `Catch` bloques pueden comunicar correctamente las excepciones a los usuarios, ya sea a través de subprocesos registro o los mensajes adecuados.</span><span class="sxs-lookup"><span data-stu-id="b6d2a-198">Ensure that code in `Catch` blocks can properly report exceptions to users, whether through thread-safe logging or appropriate messages.</span></span> <span data-ttu-id="b6d2a-199">En caso contrario, las excepciones pueden permanecer desconocidas.</span><span class="sxs-lookup"><span data-stu-id="b6d2a-199">Otherwise, exceptions might remain unknown.</span></span>

## <a name="async-methods"></a><span data-ttu-id="b6d2a-200">Métodos asincrónicos</span><span class="sxs-lookup"><span data-stu-id="b6d2a-200">Async methods</span></span>

<span data-ttu-id="b6d2a-201">Si marca un método con el [Async](../modifiers/async.md) modificador, puede usar el [Await](../operators/await-operator.md) operador en el método.</span><span class="sxs-lookup"><span data-stu-id="b6d2a-201">If you mark a method with the [Async](../modifiers/async.md) modifier, you can use the [Await](../operators/await-operator.md) operator in the method.</span></span> <span data-ttu-id="b6d2a-202">Una instrucción con el `Await` operador suspende la ejecución del método hasta que se complete la tarea esperada.</span><span class="sxs-lookup"><span data-stu-id="b6d2a-202">A statement with the `Await` operator suspends execution of the method until the awaited task completes.</span></span> <span data-ttu-id="b6d2a-203">La tarea representa el trabajo en curso.</span><span class="sxs-lookup"><span data-stu-id="b6d2a-203">The task represents ongoing work.</span></span> <span data-ttu-id="b6d2a-204">Cuando la tarea que está asociada el `Await` operador finaliza, se reanuda la ejecución en el mismo método.</span><span class="sxs-lookup"><span data-stu-id="b6d2a-204">When the task that's associated with the `Await` operator finishes, execution resumes in the same method.</span></span> <span data-ttu-id="b6d2a-205">Para obtener más información, consulte [flujo de Control en programas Async](../../../visual-basic/programming-guide/concepts/async/control-flow-in-async-programs.md).</span><span class="sxs-lookup"><span data-stu-id="b6d2a-205">For more information, see [Control Flow in Async Programs](../../../visual-basic/programming-guide/concepts/async/control-flow-in-async-programs.md).</span></span>

<span data-ttu-id="b6d2a-206">Una tarea devuelta por un método asincrónico puede terminar en un estado de error que indica que ha completado debido a una excepción no controlada.</span><span class="sxs-lookup"><span data-stu-id="b6d2a-206">A task returned by an Async method may end in a faulted state, indicating that it completed due to an unhandled exception.</span></span> <span data-ttu-id="b6d2a-207">También puede finalizar una tarea en un estado cancelado, lo que da como resultado un `OperationCanceledException` que se produzca fuera de la expresión await.</span><span class="sxs-lookup"><span data-stu-id="b6d2a-207">A task may also end in a canceled state, which results in an `OperationCanceledException` being thrown out of the await expression.</span></span> <span data-ttu-id="b6d2a-208">Para detectar cualquier tipo de excepción, coloque el `Await` expresión asociada con la tarea en un `Try` bloquear y detectar la excepción en el `Catch` bloque.</span><span class="sxs-lookup"><span data-stu-id="b6d2a-208">To catch either type of exception, place the `Await` expression that's associated with the task in a `Try` block, and catch the exception in the `Catch` block.</span></span> <span data-ttu-id="b6d2a-209">Más adelante en este tema se proporciona un ejemplo.</span><span class="sxs-lookup"><span data-stu-id="b6d2a-209">An example is provided later in this topic.</span></span>

<span data-ttu-id="b6d2a-210">Puede ser una tarea en un estado de error porque varias excepciones eran responsables de su con error.</span><span class="sxs-lookup"><span data-stu-id="b6d2a-210">A task can be in a faulted state because multiple exceptions were responsible for its faulting.</span></span> <span data-ttu-id="b6d2a-211">Por ejemplo, la tarea podría ser el resultado de una llamada a <xref:System.Threading.Tasks.Task.WhenAll%2A?displayProperty=nameWithType>.</span><span class="sxs-lookup"><span data-stu-id="b6d2a-211">For example, the task might be the result of a call to <xref:System.Threading.Tasks.Task.WhenAll%2A?displayProperty=nameWithType>.</span></span> <span data-ttu-id="b6d2a-212">Cuando espera dicha tarea, la excepción detectada es solo una de las excepciones y no puede predecir qué excepción se capturará.</span><span class="sxs-lookup"><span data-stu-id="b6d2a-212">When you await such a task, the caught exception is only one of the exceptions, and you can't predict which exception will be caught.</span></span> <span data-ttu-id="b6d2a-213">Más adelante en este tema se proporciona un ejemplo.</span><span class="sxs-lookup"><span data-stu-id="b6d2a-213">An example is provided later in this topic.</span></span>

<span data-ttu-id="b6d2a-214">Un `Await` expresión no puede estar dentro de un `Catch` bloque o `Finally` bloque.</span><span class="sxs-lookup"><span data-stu-id="b6d2a-214">An `Await` expression can't be inside a `Catch` block or `Finally` block.</span></span>

## <a name="iterators"></a><span data-ttu-id="b6d2a-215">Iterators</span><span class="sxs-lookup"><span data-stu-id="b6d2a-215">Iterators</span></span>

<span data-ttu-id="b6d2a-216">Una función de iterador o `Get` descriptor de acceso realiza una iteración personalizada en una colección.</span><span class="sxs-lookup"><span data-stu-id="b6d2a-216">An iterator function or `Get` accessor performs a custom iteration over a collection.</span></span> <span data-ttu-id="b6d2a-217">Un iterador usa una [Yield](yield-statement.md) instrucción para devolver cada elemento de la colección a la vez.</span><span class="sxs-lookup"><span data-stu-id="b6d2a-217">An iterator uses a [Yield](yield-statement.md) statement to return each element of the collection one at a time.</span></span> <span data-ttu-id="b6d2a-218">Puede llamar a una función de iterador con un [For Each... Instrucción Next](for-each-next-statement.md).</span><span class="sxs-lookup"><span data-stu-id="b6d2a-218">You call an iterator function by using a [For Each...Next Statement](for-each-next-statement.md).</span></span>

<span data-ttu-id="b6d2a-219">Un `Yield` instrucción puede estar dentro de un `Try` bloque.</span><span class="sxs-lookup"><span data-stu-id="b6d2a-219">A `Yield` statement can be inside a `Try` block.</span></span> <span data-ttu-id="b6d2a-220">Un `Try` bloque que contiene un `Yield` instrucción puede tener `Catch` bloquea y puede tener un `Finally` bloque.</span><span class="sxs-lookup"><span data-stu-id="b6d2a-220">A `Try` block that contains a `Yield` statement can have `Catch` blocks, and can have a `Finally` block.</span></span> <span data-ttu-id="b6d2a-221">Consulte la sección "Probar bloques en Visual Basic" de [iteradores](../../programming-guide/concepts/iterators.md) para obtener un ejemplo.</span><span class="sxs-lookup"><span data-stu-id="b6d2a-221">See the "Try Blocks in Visual Basic" section of [Iterators](../../programming-guide/concepts/iterators.md) for an example.</span></span>

<span data-ttu-id="b6d2a-222">Un `Yield` instrucción no puede estar dentro de un `Catch` bloque o una `Finally` bloque.</span><span class="sxs-lookup"><span data-stu-id="b6d2a-222">A `Yield` statement cannot be inside a `Catch` block or a `Finally` block.</span></span>

<span data-ttu-id="b6d2a-223">Si el `For Each` cuerpo (fuera de la función de iterador) produce una excepción, un `Catch` no se ejecuta el bloque de la función de iterador, pero un `Finally` se ejecuta el bloque de la función del iterador.</span><span class="sxs-lookup"><span data-stu-id="b6d2a-223">If the `For Each` body (outside of the iterator function) throws an exception, a `Catch` block in the iterator function is not executed, but a `Finally` block in the iterator function is executed.</span></span> <span data-ttu-id="b6d2a-224">Un `Catch` bloque dentro de una función de iterador detecta sólo las excepciones que se producen dentro de la función de iterador.</span><span class="sxs-lookup"><span data-stu-id="b6d2a-224">A `Catch` block inside an iterator function catches only exceptions that occur inside the iterator function.</span></span>

## <a name="partial-trust-situations"></a><span data-ttu-id="b6d2a-225">Situaciones de confianza parcial</span><span class="sxs-lookup"><span data-stu-id="b6d2a-225">Partial-trust situations</span></span>

<span data-ttu-id="b6d2a-226">En situaciones de confianza parcial, como una aplicación hospedada en un recurso compartido de red, `Try...Catch...Finally` no detecta excepciones de seguridad que se producen antes de invoca el método que contiene la llamada.</span><span class="sxs-lookup"><span data-stu-id="b6d2a-226">In partial-trust situations, such as an application hosted on a network share, `Try...Catch...Finally` does not catch security exceptions that occur before the method that contains the call is invoked.</span></span> <span data-ttu-id="b6d2a-227">El ejemplo siguiente, cuando se coloca en un recurso compartido de servidor y ejecute desde allí, produce el error "System.Security.SecurityException: Error en la solicitud."</span><span class="sxs-lookup"><span data-stu-id="b6d2a-227">The following example, when you put it on a server share and run from there, produces the error "System.Security.SecurityException: Request Failed."</span></span> <span data-ttu-id="b6d2a-228">Para obtener más información sobre las excepciones de seguridad, consulte el <xref:System.Security.SecurityException> clase.</span><span class="sxs-lookup"><span data-stu-id="b6d2a-228">For more information about security exceptions, see the <xref:System.Security.SecurityException> class.</span></span>

[!code-vb[VbVbalrStatements#85](~/samples/snippets/visualbasic/VS_Snippets_VBCSharp/VbVbalrStatements/VB/Class1.vb#85)]

<span data-ttu-id="b6d2a-229">En esta situación de confianza parcial, tendrá que colocar el `Process.Start` instrucción en otro `Sub`.</span><span class="sxs-lookup"><span data-stu-id="b6d2a-229">In such a partial-trust situation, you have to put the `Process.Start` statement in a separate `Sub`.</span></span> <span data-ttu-id="b6d2a-230">La llamada inicial a la `Sub` se producirá un error.</span><span class="sxs-lookup"><span data-stu-id="b6d2a-230">The initial call to the `Sub` will fail.</span></span> <span data-ttu-id="b6d2a-231">Esto permite `Try...Catch` capturarla antes el `Sub` que contiene `Process.Start` se inicia y se produce la excepción de seguridad.</span><span class="sxs-lookup"><span data-stu-id="b6d2a-231">This enables `Try...Catch` to catch it before the `Sub` that contains `Process.Start` is started and the security exception produced.</span></span>

## <a name="examples"></a><span data-ttu-id="b6d2a-232">Ejemplos</span><span class="sxs-lookup"><span data-stu-id="b6d2a-232">Examples</span></span>

### <a name="the-structure-of-trycatchfinally"></a><span data-ttu-id="b6d2a-233">La estructura de Try... Catch... Por último</span><span class="sxs-lookup"><span data-stu-id="b6d2a-233">The structure of Try...Catch...Finally</span></span>

<span data-ttu-id="b6d2a-234">El ejemplo siguiente muestra la estructura de la `Try...Catch...Finally` instrucción.</span><span class="sxs-lookup"><span data-stu-id="b6d2a-234">The following example illustrates the structure of the `Try...Catch...Finally` statement.</span></span>

[!code-vb[VbVbalrStatements#86](~/samples/snippets/visualbasic/VS_Snippets_VBCSharp/VbVbalrStatements/VB/Class1.vb#86)]  

### <a name="exception-in-a-method-called-from-a-try-block"></a><span data-ttu-id="b6d2a-235">Excepción en un método llamado desde un bloque Try</span><span class="sxs-lookup"><span data-stu-id="b6d2a-235">Exception in a method called from a Try block</span></span>

<span data-ttu-id="b6d2a-236">En el ejemplo siguiente, la `CreateException` método produce una `NullReferenceException`.</span><span class="sxs-lookup"><span data-stu-id="b6d2a-236">In the following example, the `CreateException` method throws a `NullReferenceException`.</span></span> <span data-ttu-id="b6d2a-237">El código que genera la excepción no está en un `Try` bloque.</span><span class="sxs-lookup"><span data-stu-id="b6d2a-237">The code that generates the exception is not in a `Try` block.</span></span> <span data-ttu-id="b6d2a-238">Por lo tanto, el `CreateException` método no controla la excepción.</span><span class="sxs-lookup"><span data-stu-id="b6d2a-238">Therefore, the `CreateException` method does not handle the exception.</span></span> <span data-ttu-id="b6d2a-239">El `RunSample` método controlar la excepción porque la llamada a la `CreateException` método está en un `Try` bloque.</span><span class="sxs-lookup"><span data-stu-id="b6d2a-239">The `RunSample` method does handle the exception because the call to the `CreateException` method is in a `Try` block.</span></span>

<span data-ttu-id="b6d2a-240">El ejemplo incluye `Catch` instrucciones para varios tipos de excepciones, ordenada desde el más específico al más general.</span><span class="sxs-lookup"><span data-stu-id="b6d2a-240">The example includes `Catch` statements for several types of exceptions, ordered from the most specific to the most general.</span></span>

[!code-vb[VbVbalrStatements#91](~/samples/snippets/visualbasic/VS_Snippets_VBCSharp/VbVbalrStatements/VB/Class1.vb#91)]

### <a name="the-catch-when-statement"></a><span data-ttu-id="b6d2a-241">La instrucción Catch cuando</span><span class="sxs-lookup"><span data-stu-id="b6d2a-241">The Catch When statement</span></span>

<span data-ttu-id="b6d2a-242">El ejemplo siguiente muestra cómo usar un `Catch When` instrucción filtrar en una expresión condicional.</span><span class="sxs-lookup"><span data-stu-id="b6d2a-242">The following example shows how to use a `Catch When` statement to filter on a conditional expression.</span></span> <span data-ttu-id="b6d2a-243">Si la expresión condicional se evalúa como `True`, el código en el `Catch` bloquear ejecuciones.</span><span class="sxs-lookup"><span data-stu-id="b6d2a-243">If the conditional expression evaluates to `True`, the code in the `Catch` block runs.</span></span>

[!code-vb[VbVbalrStatements#92](~/samples/snippets/visualbasic/VS_Snippets_VBCSharp/VbVbalrStatements/VB/Class1.vb#92)]

### <a name="nested-try-statements"></a><span data-ttu-id="b6d2a-244">Instrucciones Try anidadas</span><span class="sxs-lookup"><span data-stu-id="b6d2a-244">Nested Try statements</span></span>

<span data-ttu-id="b6d2a-245">El siguiente ejemplo tiene un `Try…Catch` instrucción que se encuentra en un `Try` bloque.</span><span class="sxs-lookup"><span data-stu-id="b6d2a-245">The following example has a `Try…Catch` statement that is contained in a `Try` block.</span></span> <span data-ttu-id="b6d2a-246">Interno `Catch` bloque produce una excepción que tiene su `InnerException` propiedad establecida en la excepción original.</span><span class="sxs-lookup"><span data-stu-id="b6d2a-246">The inner `Catch` block throws an exception that has its `InnerException` property set to the original exception.</span></span> <span data-ttu-id="b6d2a-247">El exterior `Catch` bloque informa acerca de su propia excepción y la excepción interna.</span><span class="sxs-lookup"><span data-stu-id="b6d2a-247">The outer `Catch` block reports its own exception and the inner exception.</span></span>

[!code-vb[VbVbalrStatements#93](~/samples/snippets/visualbasic/VS_Snippets_VBCSharp/VbVbalrStatements/VB/Class1.vb#93)]

### <a name="exception-handling-for-async-methods"></a><span data-ttu-id="b6d2a-248">Control de excepciones para los métodos asincrónicos</span><span class="sxs-lookup"><span data-stu-id="b6d2a-248">Exception handling for async methods</span></span>

<span data-ttu-id="b6d2a-249">En el ejemplo siguiente se muestra el control de excepciones de los métodos asincrónicos.</span><span class="sxs-lookup"><span data-stu-id="b6d2a-249">The following example illustrates exception handling for async methods.</span></span> <span data-ttu-id="b6d2a-250">Para detectar una excepción que se aplica a una tarea asincrónica, el `Await` expresión está en un `Try` bloque del autor de la llamada y la excepción se captura en el `Catch` bloque.</span><span class="sxs-lookup"><span data-stu-id="b6d2a-250">To catch an exception that applies to an async task, the `Await` expression is in a `Try` block of the caller, and the exception is caught in the `Catch` block.</span></span>

<span data-ttu-id="b6d2a-251">Quite la marca de comentario de la línea `Throw New Exception` en el ejemplo para demostrar el control de excepciones.</span><span class="sxs-lookup"><span data-stu-id="b6d2a-251">Uncomment the `Throw New Exception` line in the example to demonstrate exception handling.</span></span> <span data-ttu-id="b6d2a-252">Se detectó la excepción en el `Catch` bloquea, la tarea `IsFaulted` propiedad está establecida en `True`y la tarea `Exception.InnerException` propiedad se establece en la excepción.</span><span class="sxs-lookup"><span data-stu-id="b6d2a-252">The exception is caught in the `Catch` block, the task's `IsFaulted` property is set to `True`, and the task's `Exception.InnerException` property is set to the exception.</span></span>

<span data-ttu-id="b6d2a-253">Quite la marca de comentario de la línea `Throw New OperationCancelledException` para ver lo que pasa cuando se cancela un proceso asincrónico.</span><span class="sxs-lookup"><span data-stu-id="b6d2a-253">Uncomment the `Throw New OperationCancelledException` line to demonstrate what happens when you cancel an asynchronous process.</span></span> <span data-ttu-id="b6d2a-254">Se detectó la excepción en el `Catch` bloque y la tarea `IsCanceled` propiedad está establecida en `True`.</span><span class="sxs-lookup"><span data-stu-id="b6d2a-254">The exception is caught in the `Catch` block, and the task's `IsCanceled` property is set to `True`.</span></span> <span data-ttu-id="b6d2a-255">Sin embargo, en algunas condiciones que no son aplicables a este ejemplo, `IsFaulted` está establecido en `True` y `IsCanceled` está establecido en `False`.</span><span class="sxs-lookup"><span data-stu-id="b6d2a-255">However, under some conditions that don't apply to this example, `IsFaulted` is set to `True` and `IsCanceled` is set to `False`.</span></span>

[!code-vb[csAsyncExceptions#1](~/samples/snippets/visualbasic/VS_Snippets_VBCSharp/csasyncexceptions/vb/class1.vb#1)]

### <a name="handling-multiple-exceptions-in-async-methods"></a><span data-ttu-id="b6d2a-256">Control de varias excepciones en métodos asincrónicos</span><span class="sxs-lookup"><span data-stu-id="b6d2a-256">Handling multiple exceptions in async methods</span></span>

<span data-ttu-id="b6d2a-257">En el ejemplo siguiente se muestra el control de excepciones en el que varias tareas pueden producir varias excepciones.</span><span class="sxs-lookup"><span data-stu-id="b6d2a-257">The following example illustrates exception handling where multiple tasks can result in multiple exceptions.</span></span> <span data-ttu-id="b6d2a-258">El `Try` bloque tiene el `Await` expresión para la tarea que <xref:System.Threading.Tasks.Task.WhenAll%2A?displayProperty=nameWithType> devuelto.</span><span class="sxs-lookup"><span data-stu-id="b6d2a-258">The `Try` block has the `Await` expression for the task that <xref:System.Threading.Tasks.Task.WhenAll%2A?displayProperty=nameWithType> returned.</span></span> <span data-ttu-id="b6d2a-259">La tarea está completa cuando las tres tareas a la que <xref:System.Threading.Tasks.Task.WhenAll%2A?displayProperty=nameWithType> se aplica están completos.</span><span class="sxs-lookup"><span data-stu-id="b6d2a-259">The task is complete when the three tasks to which <xref:System.Threading.Tasks.Task.WhenAll%2A?displayProperty=nameWithType> is applied are complete.</span></span>

<span data-ttu-id="b6d2a-260">Cada una de las tres tareas produce una excepción.</span><span class="sxs-lookup"><span data-stu-id="b6d2a-260">Each of the three tasks causes an exception.</span></span> <span data-ttu-id="b6d2a-261">El `Catch` bloque recorre en iteración las excepciones, que se encuentran en el `Exception.InnerExceptions` propiedad de la tarea que `Task.WhenAll` devuelto.</span><span class="sxs-lookup"><span data-stu-id="b6d2a-261">The `Catch` block iterates through the exceptions, which are found in the `Exception.InnerExceptions` property of the task that `Task.WhenAll` returned.</span></span>

[!code-vb[csAsyncExceptions#3](~/samples/snippets/visualbasic/VS_Snippets_VBCSharp/csasyncexceptions/vb/class1.vb#3)]

## <a name="see-also"></a><span data-ttu-id="b6d2a-262">Vea también</span><span class="sxs-lookup"><span data-stu-id="b6d2a-262">See also</span></span>

- <xref:Microsoft.VisualBasic.Information.Err%2A>
- <xref:System.Exception>
- [<span data-ttu-id="b6d2a-263">Exit (instrucción)</span><span class="sxs-lookup"><span data-stu-id="b6d2a-263">Exit Statement</span></span>](exit-statement.md)
- [<span data-ttu-id="b6d2a-264">On Error (instrucción)</span><span class="sxs-lookup"><span data-stu-id="b6d2a-264">On Error Statement</span></span>](on-error-statement.md)
- [<span data-ttu-id="b6d2a-265">Procedimientos recomendados para usar fragmentos de código</span><span class="sxs-lookup"><span data-stu-id="b6d2a-265">Best Practices for Using Code Snippets</span></span>](/visualstudio/ide/best-practices-for-using-code-snippets)
- [<span data-ttu-id="b6d2a-266">Control de excepciones</span><span class="sxs-lookup"><span data-stu-id="b6d2a-266">Exception Handling</span></span>](../../../standard/parallel-programming/exception-handling-task-parallel-library.md)
- [<span data-ttu-id="b6d2a-267">Throw (instrucción)</span><span class="sxs-lookup"><span data-stu-id="b6d2a-267">Throw Statement</span></span>](throw-statement.md)